Traceback (most recent call last):
  File "/usr/share/miniconda/envs/tutorial/lib/python3.8/site-packages/jupyter_cache/executors/utils.py", line 51, in single_nb_execution
    executenb(
  File "/usr/share/miniconda/envs/tutorial/lib/python3.8/site-packages/nbclient/client.py", line 1204, in execute
    return NotebookClient(nb=nb, resources=resources, km=km, **kwargs).execute()
  File "/usr/share/miniconda/envs/tutorial/lib/python3.8/site-packages/nbclient/util.py", line 84, in wrapped
    return just_run(coro(*args, **kwargs))
  File "/usr/share/miniconda/envs/tutorial/lib/python3.8/site-packages/nbclient/util.py", line 62, in just_run
    return loop.run_until_complete(coro)
  File "/usr/share/miniconda/envs/tutorial/lib/python3.8/asyncio/base_events.py", line 616, in run_until_complete
    return future.result()
  File "/usr/share/miniconda/envs/tutorial/lib/python3.8/site-packages/nbclient/client.py", line 663, in async_execute
    await self.async_execute_cell(
  File "/usr/share/miniconda/envs/tutorial/lib/python3.8/site-packages/nbclient/client.py", line 965, in async_execute_cell
    await self._check_raise_for_error(cell, cell_index, exec_reply)
  File "/usr/share/miniconda/envs/tutorial/lib/python3.8/site-packages/nbclient/client.py", line 862, in _check_raise_for_error
    raise CellExecutionError.from_cell_and_msg(cell, exec_reply_content)
nbclient.exceptions.CellExecutionError: An error occurred while executing the following cell:
------------------
from wis_downloader import downloader
downloader.download_sigletasking(url=hrefs[0],file_name='../data/dem/dem.tif')
------------------

[0;31m---------------------------------------------------------------------------[0m
[0;31mFileNotFoundError[0m                         Traceback (most recent call last)
Cell [0;32mIn [2], line 2[0m
[1;32m      1[0m [38;5;28;01mfrom[39;00m [38;5;21;01mwis_downloader[39;00m [38;5;28;01mimport[39;00m downloader
[0;32m----> 2[0m downloader[38;5;241m.[39mdownload_sigletasking(url[38;5;241m=[39mhrefs[[38;5;241m0[39m],file_name[38;5;241m=[39m[38;5;124m'[39m[38;5;124m../data/dem/dem.tif[39m[38;5;124m'[39m)

File [0;32m/usr/share/miniconda/envs/tutorial/lib/python3.8/site-packages/wis_downloader/downloader.py:90[0m, in [0;36mdownload_sigletasking[0;34m(url, file_name)[0m
[1;32m     88[0m chunk_size [38;5;241m=[39m [38;5;28mint[39m(file_size[38;5;241m/[39m[38;5;241m100[39m)[38;5;241m+[39m[38;5;241m1[39m
[1;32m     89[0m bar [38;5;241m=[39m tqdm(total[38;5;241m=[39mfile_size, desc[38;5;241m=[39m[38;5;124mf[39m[38;5;124m'[39m[38;5;124m‰∏ãËΩΩÊñá‰ª∂ [39m[38;5;132;01m{[39;00mfile_name[38;5;132;01m}[39;00m[38;5;124m'[39m)
[0;32m---> 90[0m [38;5;28;01mwith[39;00m [38;5;28;43mopen[39;49m[43m([49m[43mfile_name[49m[43m,[49m[43m [49m[43mmode[49m[38;5;241;43m=[39;49m[38;5;124;43m'[39;49m[38;5;124;43mwb[39;49m[38;5;124;43m'[39;49m[43m)[49m [38;5;28;01mas[39;00m f:
[1;32m     91[0m     [38;5;66;03m# ÂÜôÂÖ•ÂàÜÂùóÊñá‰ª∂[39;00m
[1;32m     92[0m     [38;5;28;01mfor[39;00m chunk [38;5;129;01min[39;00m response[38;5;241m.[39miter_content(chunk_size[38;5;241m=[39mchunk_size):
[1;32m     93[0m         f[38;5;241m.[39mwrite(chunk)

[0;31mFileNotFoundError[0m: [Errno 2] No such file or directory: '../data/dem/dem.tif'
FileNotFoundError: [Errno 2] No such file or directory: '../data/dem/dem.tif'

