Traceback (most recent call last):
  File "/usr/share/miniconda/envs/tutorial/lib/python3.8/site-packages/jupyter_cache/executors/utils.py", line 51, in single_nb_execution
    executenb(
  File "/usr/share/miniconda/envs/tutorial/lib/python3.8/site-packages/nbclient/client.py", line 1204, in execute
    return NotebookClient(nb=nb, resources=resources, km=km, **kwargs).execute()
  File "/usr/share/miniconda/envs/tutorial/lib/python3.8/site-packages/nbclient/util.py", line 84, in wrapped
    return just_run(coro(*args, **kwargs))
  File "/usr/share/miniconda/envs/tutorial/lib/python3.8/site-packages/nbclient/util.py", line 62, in just_run
    return loop.run_until_complete(coro)
  File "/usr/share/miniconda/envs/tutorial/lib/python3.8/asyncio/base_events.py", line 616, in run_until_complete
    return future.result()
  File "/usr/share/miniconda/envs/tutorial/lib/python3.8/site-packages/nbclient/client.py", line 663, in async_execute
    await self.async_execute_cell(
  File "/usr/share/miniconda/envs/tutorial/lib/python3.8/site-packages/nbclient/client.py", line 965, in async_execute_cell
    await self._check_raise_for_error(cell, cell_index, exec_reply)
  File "/usr/share/miniconda/envs/tutorial/lib/python3.8/site-packages/nbclient/client.py", line 862, in _check_raise_for_error
    raise CellExecutionError.from_cell_and_msg(cell, exec_reply_content)
nbclient.exceptions.CellExecutionError: An error occurred while executing the following cell:
------------------
import hydrodataset
------------------

[0;31m---------------------------------------------------------------------------[0m
[0;31mImportError[0m                               Traceback (most recent call last)
Cell [0;32mIn [1], line 1[0m
[0;32m----> 1[0m [38;5;28;01mimport[39;00m [38;5;21;01mhydrodataset[39;00m

File [0;32m/usr/share/miniconda/envs/tutorial/lib/python3.8/site-packages/hydrodataset/__init__.py:47[0m
[1;32m     45[0m CACHE_DIR [38;5;241m=[39m hydrodataset_cache_dir
[1;32m     46[0m [38;5;28;01mfrom[39;00m [38;5;21;01m.[39;00m[38;5;21;01mhydro_dataset[39;00m [38;5;28;01mimport[39;00m [38;5;241m*[39m
[0;32m---> 47[0m [38;5;28;01mfrom[39;00m [38;5;21;01m.[39;00m[38;5;21;01mcamels[39;00m [38;5;28;01mimport[39;00m [38;5;241m*[39m

File [0;32m/usr/share/miniconda/envs/tutorial/lib/python3.8/site-packages/hydrodataset/camels.py:10[0m
[1;32m      1[0m [38;5;124;03m"""[39;00m
[1;32m      2[0m [38;5;124;03mAuthor: Wenyu Ouyang[39;00m
[1;32m      3[0m [38;5;124;03mDate: 2022-01-05 18:01:11[39;00m
[0;32m   (...)[0m
[1;32m      8[0m [38;5;124;03mCopyright (c) 2021-2022 Wenyu Ouyang. All rights reserved.[39;00m
[1;32m      9[0m [38;5;124;03m"""[39;00m
[0;32m---> 10[0m [38;5;28;01mfrom[39;00m [38;5;21;01mfunctools[39;00m [38;5;28;01mimport[39;00m cache
[1;32m     11[0m [38;5;28;01mfrom[39;00m [38;5;21;01mgenericpath[39;00m [38;5;28;01mimport[39;00m isfile
[1;32m     12[0m [38;5;28;01mimport[39;00m [38;5;21;01mjson[39;00m

[0;31mImportError[0m: cannot import name 'cache' from 'functools' (/usr/share/miniconda/envs/tutorial/lib/python3.8/functools.py)
ImportError: cannot import name 'cache' from 'functools' (/usr/share/miniconda/envs/tutorial/lib/python3.8/functools.py)

