Traceback (most recent call last):
  File "/usr/share/miniconda/envs/tutorial/lib/python3.8/site-packages/jupyter_cache/executors/utils.py", line 58, in single_nb_execution
    executenb(
  File "/usr/share/miniconda/envs/tutorial/lib/python3.8/site-packages/nbclient/client.py", line 1305, in execute
    return NotebookClient(nb=nb, resources=resources, km=km, **kwargs).execute()
  File "/usr/share/miniconda/envs/tutorial/lib/python3.8/site-packages/jupyter_core/utils/__init__.py", line 165, in wrapped
    return loop.run_until_complete(inner)
  File "/usr/share/miniconda/envs/tutorial/lib/python3.8/asyncio/base_events.py", line 616, in run_until_complete
    return future.result()
  File "/usr/share/miniconda/envs/tutorial/lib/python3.8/site-packages/nbclient/client.py", line 705, in async_execute
    await self.async_execute_cell(
  File "/usr/share/miniconda/envs/tutorial/lib/python3.8/site-packages/nbclient/client.py", line 1058, in async_execute_cell
    await self._check_raise_for_error(cell, cell_index, exec_reply)
  File "/usr/share/miniconda/envs/tutorial/lib/python3.8/site-packages/nbclient/client.py", line 914, in _check_raise_for_error
    raise CellExecutionError.from_cell_and_msg(cell, exec_reply_content)
nbclient.exceptions.CellExecutionError: An error occurred while executing the following cell:
------------------
boulder_precip_in = [0.70, 0.75, 1.85]
boulder_precip_in *= 25.4
------------------


[0;31m---------------------------------------------------------------------------[0m
[0;31mTypeError[0m                                 Traceback (most recent call last)
Cell [0;32mIn[5], line 2[0m
[1;32m      1[0m boulder_precip_in [38;5;241m=[39m [[38;5;241m0.70[39m, [38;5;241m0.75[39m, [38;5;241m1.85[39m]
[0;32m----> 2[0m boulder_precip_in [38;5;241m*[39m[38;5;241m=[39m [38;5;241m25.4[39m

[0;31mTypeError[0m: can't multiply sequence by non-int of type 'float'

